Workbook

Sheet LEG ESTUDO DE MASSAS
F1: 45547 | J1: PESQUISAR CÓDIGO ANTIGO:
B3: CLIENTE - PROJETO | K3: COD. ANTIGO | L3: COD. NOVO | M3: NOME | N3: NOME
B4: LEGENDAS ESPÉCIES ESTUDO DE MASSAS | K4: TAIM | L4: =_xlfn.XLOOKUP(K$4,'uso interno PLANILHA'!R:R,'uso interno PLANILHA'!A:A,0) -> HAIM | M4: =_xlfn.XLOOKUP(L4,'uso interno PLANILHA'!A:A,'uso interno PLANILHA'!C:C,0) -> Handroanthus impetiginosus (Tabebuia impetiginosa ) | N4: =_xlfn.XLOOKUP(L4,'uso interno PLANILHA'!A:A,'uso interno PLANILHA'!D:D,0) -> Ipe roxo de bola
B5: ÁRVORES/ PALMEIRAS/ ARBUSTOS / FORRAÇÕES
B6: CODIGO | C6: TIPO | D6: NOME CIENTIFICO | E6: NOME POPULAR | F6: COR
B7: CLFL VA | C7: =VLOOKUP($B7,DADOS_ABBUD[],COLUMNS($C$6:C6)+1,0) -> 5. ARBUSTO | D7: =VLOOKUP($B7,DADOS_ABBUD[],COLUMNS($C$6:D6)+1,0) -> Clusia fluminensis variegata | E7: =VLOOKUP($B7,DADOS_ABBUD[],COLUMNS($C$6:E6)+1,0) -> Clúsia-grande | F7: =VLOOKUP($B7,DADOS_ABBUD[],COLUMNS($C$6:F6)+1,0) -> VARIEGATA
B8: ARRE | C8: =VLOOKUP($B8,DADOS_ABBUD[],COLUMNS($C$6:C7)+1,0) -> 6. FORRAÇÃO | D8: =VLOOKUP($B8,DADOS_ABBUD[],COLUMNS($C$6:D7)+1,0) -> Arachis repens | E8: =VLOOKUP($B8,DADOS_ABBUD[],COLUMNS($C$6:E7)+1,0) -> Grama amendoim | F8: =VLOOKUP($B8,DADOS_ABBUD[],COLUMNS($C$6:F7)+1,0) -> AMARELO
B9: ASSP | C9: =VLOOKUP($B9,DADOS_ABBUD[],COLUMNS($C$6:C8)+1,0) -> 6. FORRAÇÃO | D9: =VLOOKUP($B9,DADOS_ABBUD[],COLUMNS($C$6:D8)+1,0) -> Asparagus densiflorus Sprengeri | E9: =VLOOKUP($B9,DADOS_ABBUD[],COLUMNS($C$6:E8)+1,0) -> Aspargo pendente | F9: =VLOOKUP($B9,DADOS_ABBUD[],COLUMNS($C$6:F8)+1,0)
B10: CAJA | C10: =VLOOKUP($B10,DADOS_ABBUD[],COLUMNS($C$6:C9)+1,0) -> 5. ARBUSTO | D10: =VLOOKUP($B10,DADOS_ABBUD[],COLUMNS($C$6:D9)+1,0) -> Camellia japonica | E10: =VLOOKUP($B10,DADOS_ABBUD[],COLUMNS($C$6:E9)+1,0) -> Camelia | F10: =VLOOKUP($B10,DADOS_ABBUD[],COLUMNS($C$6:F9)+1,0) -> BR RS
B11: CALU | C11: =VLOOKUP($B11,DADOS_ABBUD[],COLUMNS($C$6:C10)+1,0) -> 5. ARBUSTO | D11: =VLOOKUP($B11,DADOS_ABBUD[],COLUMNS($C$6:D10)+1,0) -> Calathea lutea | E11: =VLOOKUP($B11,DADOS_ABBUD[],COLUMNS($C$6:E10)+1,0) -> Calatéia Charuto | F11: =VLOOKUP($B11,DADOS_ABBUD[],COLUMNS($C$6:F10)+1,0)
B12: CUCA | C12: =VLOOKUP($B12,DADOS_ABBUD[],COLUMNS($C$6:C11)+1,0) -> 5. ARBUSTO | D12: =VLOOKUP($B12,DADOS_ABBUD[],COLUMNS($C$6:D11)+1,0) -> Curculigo capitulata | E12: =VLOOKUP($B12,DADOS_ABBUD[],COLUMNS($C$6:E11)+1,0) -> Curculigo | F12: =VLOOKUP($B12,DADOS_ABBUD[],COLUMNS($C$6:F11)+1,0)
B13: CYBI | C13: =VLOOKUP($B13,DADOS_ABBUD[],COLUMNS($C$6:C12)+1,0) -> 5. ARBUSTO | D13: =VLOOKUP($B13,DADOS_ABBUD[],COLUMNS($C$6:D12)+1,0) -> Cyclanthus bipartitus | E13: =VLOOKUP($B13,DADOS_ABBUD[],COLUMNS($C$6:E12)+1,0) -> Ciclantus | F13: =VLOOKUP($B13,DADOS_ABBUD[],COLUMNS($C$6:F12)+1,0)
B14: DRAR | C14: =VLOOKUP($B14,DADOS_ABBUD[],COLUMNS($C$6:C13)+1,0) -> 5. ARBUSTO | D14: =VLOOKUP($B14,DADOS_ABBUD[],COLUMNS($C$6:D13)+1,0) -> Dracaena arborea | E14: =VLOOKUP($B14,DADOS_ABBUD[],COLUMNS($C$6:E13)+1,0) -> Dracena arbórea | F14: =VLOOKUP($B14,DADOS_ABBUD[],COLUMNS($C$6:F13)+1,0)
B15: DYMA | C15: =VLOOKUP($B15,DADOS_ABBUD[],COLUMNS($C$6:C14)+1,0) -> 1. PALMEIRA | D15: =VLOOKUP($B15,DADOS_ABBUD[],COLUMNS($C$6:D14)+1,0) -> Dypsis madagascariensis | E15: =VLOOKUP($B15,DADOS_ABBUD[],COLUMNS($C$6:E14)+1,0) -> Areca de locuba | F15: =VLOOKUP($B15,DADOS_ABBUD[],COLUMNS($C$6:F14)+1,0)
B16: EUUN | C16: =VLOOKUP($B16,DADOS_ABBUD[],COLUMNS($C$6:C15)+1,0) -> 4. ARV FRUT | D16: =VLOOKUP($B16,DADOS_ABBUD[],COLUMNS($C$6:D15)+1,0) -> Eugenia uniflora | E16: =VLOOKUP($B16,DADOS_ABBUD[],COLUMNS($C$6:E15)+1,0) -> Pitanga | F16: =VLOOKUP($B16,DADOS_ABBUD[],COLUMNS($C$6:F15)+1,0)
B17: GAJA | C17: =VLOOKUP($B17,DADOS_ABBUD[],COLUMNS($C$6:C16)+1,0) -> 5. ARBUSTO | D17: =VLOOKUP($B17,DADOS_ABBUD[],COLUMNS($C$6:D16)+1,0) -> Gardenia jasminoides | E17: =VLOOKUP($B17,DADOS_ABBUD[],COLUMNS($C$6:E16)+1,0) -> Gardenia | F17: =VLOOKUP($B17,DADOS_ABBUD[],COLUMNS($C$6:F16)+1,0) -> BRANCO
B18: HACH | C18: =VLOOKUP($B18,DADOS_ABBUD[],COLUMNS($C$6:C17)+1,0) -> 2. ARV NATIVA | D18: =VLOOKUP($B18,DADOS_ABBUD[],COLUMNS($C$6:D17)+1,0) -> Handroanthus chrysotrichus (Tabebuia chrysotricha) | E18: =VLOOKUP($B18,DADOS_ABBUD[],COLUMNS($C$6:E17)+1,0) -> Ipe amarelo cascudo | F18: =VLOOKUP($B18,DADOS_ABBUD[],COLUMNS($C$6:F17)+1,0) -> AMARELO
... B46: MEER | C46: =VLOOKUP($B46,DADOS_ABBUD[],COLUMNS($C$6:C45)+1,0) -> 5. ARBUSTO | D46: =VLOOKUP($B46,DADOS_ABBUD[],COLUMNS($C$6:D45)+1,0) -> Megaskepasma erythrochlamys | E46: =VLOOKUP($B46,DADOS_ABBUD[],COLUMNS($C$6:E45)+1,0) -> Justicia vermelha | F46: =VLOOKUP($B46,DADOS_ABBUD[],COLUMNS($C$6:F45)+1,0) -> 0
K47: COMO USAR A PLANILHA:
K48: 1) AJUSTAR DATA
K49: 2) PREENCHER CLIENTE - PROJETO
K50: 3) DIGITAR APENAS O CÓDIGO (DEMAIS COLUNAS AUTOMÁTICAS)
K51: CASO NÃO APAREÇA AS DESCRIÇÕES, SIGNIFICA Q NÃO EXISTE NO BANCO DE DADOS
K52: 4) COR: CASO NÃO SEJA A COR PRETENDIDA, ESCREVER NO CAMPO "COR"
K53: 5) IMPRESSÃO PRÉ CONFIGURADA PARA 1 FOLHA:
K54: AUTOMÁTICO - NOME DO ARQUIVO NO CABEÇALHO, BABBUD NO RODAPÉ
K55: EM "ARQUIVO" "IMPRIMIR" - VERIFICAR SE TODAS AS FOLHAS ESTÃO APARECENDO
K56: CASO NÃO, VOLTAR E SELECIONAR A PLANILHA
K57: 5) ENVIAR PARA O CLIENTE APENAS O PDF DA LEGENDA, NÃO ENVIAR O EXCEL

Sheet LEG MASSAS SIMPLIF
D1: 46097 | I1: PESQUISAR CÓDIGO ANTIGO:
B3: CLIENTE - PROJETO | J3: COD. ANTIGO | K3: COD. NOVO | L3: NOME | M3: NOME
B4: LEGENDA DE ESPÉCIES (ÁRVORES, PALMEIRAS, ARBUSTOS E FORRAÇÕES) | J4: HIPE | K4: =_xlfn.XLOOKUP(J$4,'uso interno PLANILHA'!R:R,'uso interno PLANILHA'!A:A,0) -> TAPR | L4: =_xlfn.XLOOKUP(K$4,'uso interno PLANILHA'!A:A,'uso interno PLANILHA'!C:C,0) -> Talipariti pernambucense (Hibiscus pernambucensis) | M4: =_xlfn.XLOOKUP(K$4,'uso interno PLANILHA'!A:A,'uso interno PLANILHA'!D:D,0) -> Algodão-de-praia
B5: CODIGO | C5: NOME CIENTÍFICO | D5: FOTO
B6: ='LEG ESTUDO DE MASSAS'!$B7 -> CLFL VA | C6: =VLOOKUP($B6,DADOS_ABBUD[],COLUMNS($C$5:C5)+2,0) -> Clusia fluminensis variegata | D6: =VLOOKUP($B6,DADOS_ABBUD[],COLUMNS($C$6:D6)+18,0) -> #VALUE!
B7: ='LEG ESTUDO DE MASSAS'!$B8 -> ARRE | C7: =VLOOKUP($B7,DADOS_ABBUD[],COLUMNS($C$5:C6)+2,0) -> Arachis repens | D7: =VLOOKUP($B7,DADOS_ABBUD[],COLUMNS($C$6:D7)+18,0) -> #VALUE!
B8: ='LEG ESTUDO DE MASSAS'!$B9 -> ASSP | C8: =VLOOKUP($B8,DADOS_ABBUD[],COLUMNS($C$5:C7)+2,0) -> Asparagus densiflorus Sprengeri | D8: =VLOOKUP($B8,DADOS_ABBUD[],COLUMNS($C$6:D8)+18,0) -> #VALUE!
B9: ='LEG ESTUDO DE MASSAS'!$B10 -> CAJA | C9: =VLOOKUP($B9,DADOS_ABBUD[],COLUMNS($C$5:C8)+2,0) -> Camellia japonica | D9: =VLOOKUP($B9,DADOS_ABBUD[],COLUMNS($C$6:D9)+18,0) -> #VALUE!
B10: ='LEG ESTUDO DE MASSAS'!$B11 -> CALU | C10: =VLOOKUP($B10,DADOS_ABBUD[],COLUMNS($C$5:C9)+2,0) -> Calathea lutea | D10: =VLOOKUP($B10,DADOS_ABBUD[],COLUMNS($C$6:D10)+18,0) -> #VALUE!
B11: ='LEG ESTUDO DE MASSAS'!$B12 -> CUCA | C11: =VLOOKUP($B11,DADOS_ABBUD[],COLUMNS($C$5:C10)+2,0) -> Curculigo capitulata | D11: =VLOOKUP($B11,DADOS_ABBUD[],COLUMNS($C$6:D11)+18,0) -> #VALUE!
B12: ='LEG ESTUDO DE MASSAS'!$B13 -> CYBI | C12: =VLOOKUP($B12,DADOS_ABBUD[],COLUMNS($C$5:C11)+2,0) -> Cyclanthus bipartitus | D12: =VLOOKUP($B12,DADOS_ABBUD[],COLUMNS($C$6:D12)+18,0) -> #VALUE!
B13: ='LEG ESTUDO DE MASSAS'!$B14 -> DRAR | C13: =VLOOKUP($B13,DADOS_ABBUD[],COLUMNS($C$5:C12)+2,0) -> Dracaena arborea | D13: =VLOOKUP($B13,DADOS_ABBUD[],COLUMNS($C$6:D13)+18,0) -> #VALUE!
B14: ='LEG ESTUDO DE MASSAS'!$B15 -> DYMA | C14: =VLOOKUP($B14,DADOS_ABBUD[],COLUMNS($C$5:C13)+2,0) -> Dypsis madagascariensis | D14: =VLOOKUP($B14,DADOS_ABBUD[],COLUMNS($C$6:D14)+18,0) -> #VALUE!
B15: ='LEG ESTUDO DE MASSAS'!$B16 -> EUUN | C15: =VLOOKUP($B15,DADOS_ABBUD[],COLUMNS($C$5:C14)+2,0) -> Eugenia uniflora | D15: =VLOOKUP($B15,DADOS_ABBUD[],COLUMNS($C$6:D15)+18,0) -> #VALUE!
B16: ='LEG ESTUDO DE MASSAS'!$B17 -> GAJA | C16: =VLOOKUP($B16,DADOS_ABBUD[],COLUMNS($C$5:C15)+2,0) -> Gardenia jasminoides | D16: =VLOOKUP($B16,DADOS_ABBUD[],COLUMNS($C$6:D16)+18,0) -> #VALUE!
B17: ='LEG ESTUDO DE MASSAS'!$B18 -> HACH | C17: =VLOOKUP($B17,DADOS_ABBUD[],COLUMNS($C$5:C16)+2,0) -> Handroanthus chrysotrichus (Tabebuia chrysotricha) | D17: =VLOOKUP($B17,DADOS_ABBUD[],COLUMNS($C$6:D17)+18,0) -> #VALUE!
... B44: ='LEG ESTUDO DE MASSAS'!$B45 -> THUN | C44: =VLOOKUP($B44,DADOS_ABBUD[],COLUMNS($C$5:C43)+2,0) -> Thaumatophyllum undulatum (Philodendron undulatum) | D44: =VLOOKUP($B44,DADOS_ABBUD[],COLUMNS($C$6:D44)+18,0) -> #VALUE!

Sheet LEG MASSAS PORTE
D1: 46097 | I1: PESQUISAR CÓDIGO ANTIGO:
B3: CLIENTE - PROJETO | J3: COD. ANTIGO | K3: COD. NOVO | L3: NOME | M3: NOME
B4: LEGENDA DE ESPÉCIES (ÁRVORES, PALMEIRAS, ARBUSTOS E FORRAÇÕES) | J4: CAPE | K4: =_xlfn.XLOOKUP(J$4,'uso interno PLANILHA'!R:R,'uso interno PLANILHA'!A:A,0) -> CEPL | L4: =_xlfn.XLOOKUP(K$4,'uso interno PLANILHA'!A:A,'uso interno PLANILHA'!C:C,0) -> Cenostigma pluviosum (Caesalpinia peltophoroides) | M4: =_xlfn.XLOOKUP(K$4,'uso interno PLANILHA'!A:A,'uso interno PLANILHA'!D:D,0) -> Sibipiruna
B5: CODIGO | C5: NOME CIENTÍFICO | D5: FOTO | E5: PORTE (cm)
B6: ='LEG ESTUDO DE MASSAS'!$B7 -> CLFL VA | C6: =VLOOKUP($B6,DADOS_ABBUD[],COLUMNS($C$5:C5)+2,0) -> Clusia fluminensis variegata | D6: =VLOOKUP($B6,DADOS_ABBUD[],COLUMNS($C$6:D6)+18,0) -> #VALUE! | E6: =VLOOKUP($B6,DADOS_ABBUD[],COLUMNS($C$6:D6)+10,FALSE) -> 0
B7: ='LEG ESTUDO DE MASSAS'!$B8 -> ARRE | C7: =VLOOKUP($B7,DADOS_ABBUD[],COLUMNS($C$5:C6)+2,0) -> Arachis repens | D7: =VLOOKUP($B7,DADOS_ABBUD[],COLUMNS($C$6:D7)+18,0) -> #VALUE! | E7: =VLOOKUP($B7,DADOS_ABBUD[],COLUMNS($C$6:D7)+10,FALSE) -> 10
B8: ='LEG ESTUDO DE MASSAS'!$B9 -> ASSP | C8: =VLOOKUP($B8,DADOS_ABBUD[],COLUMNS($C$5:C7)+2,0) -> Asparagus densiflorus Sprengeri | D8: =VLOOKUP($B8,DADOS_ABBUD[],COLUMNS($C$6:D8)+18,0) -> #VALUE! | E8: =VLOOKUP($B8,DADOS_ABBUD[],COLUMNS($C$6:D8)+10,FALSE) -> 40
B9: ='LEG ESTUDO DE MASSAS'!$B10 -> CAJA | C9: =VLOOKUP($B9,DADOS_ABBUD[],COLUMNS($C$5:C8)+2,0) -> Camellia japonica | D9: =VLOOKUP($B9,DADOS_ABBUD[],COLUMNS($C$6:D9)+18,0) -> #VALUE! | E9: =VLOOKUP($B9,DADOS_ABBUD[],COLUMNS($C$6:D9)+10,FALSE) -> 200
B10: CEPL | C10: =VLOOKUP($B10,DADOS_ABBUD[],COLUMNS($C$5:C9)+2,0) -> Cenostigma pluviosum (Caesalpinia peltophoroides) | D10: =VLOOKUP($B10,DADOS_ABBUD[],COLUMNS($C$6:D10)+18,0) -> #VALUE! | E10: =VLOOKUP($B10,DADOS_ABBUD[],COLUMNS($C$6:D10)+10,FALSE) -> 0
B11: ='LEG ESTUDO DE MASSAS'!$B12 -> CUCA | C11: =VLOOKUP($B11,DADOS_ABBUD[],COLUMNS($C$5:C10)+2,0) -> Curculigo capitulata | D11: =VLOOKUP($B11,DADOS_ABBUD[],COLUMNS($C$6:D11)+18,0) -> #VALUE! | E11: =VLOOKUP($B11,DADOS_ABBUD[],COLUMNS($C$6:D11)+10,FALSE) -> 30
B12: ='LEG ESTUDO DE MASSAS'!$B13 -> CYBI | C12: =VLOOKUP($B12,DADOS_ABBUD[],COLUMNS($C$5:C11)+2,0) -> Cyclanthus bipartitus | D12: =VLOOKUP($B12,DADOS_ABBUD[],COLUMNS($C$6:D12)+18,0) -> #VALUE! | E12: =VLOOKUP($B12,DADOS_ABBUD[],COLUMNS($C$6:D12)+10,FALSE) -> 100
B13: ='LEG ESTUDO DE MASSAS'!$B14 -> DRAR | C13: =VLOOKUP($B13,DADOS_ABBUD[],COLUMNS($C$5:C12)+2,0) -> Dracaena arborea | D13: =VLOOKUP($B13,DADOS_ABBUD[],COLUMNS($C$6:D13)+18,0) -> #VALUE! | E13: =VLOOKUP($B13,DADOS_ABBUD[],COLUMNS($C$6:D13)+10,FALSE) -> 200
B14: ='LEG ESTUDO DE MASSAS'!$B15 -> DYMA | C14: =VLOOKUP($B14,DADOS_ABBUD[],COLUMNS($C$5:C13)+2,0) -> Dypsis madagascariensis | D14: =VLOOKUP($B14,DADOS_ABBUD[],COLUMNS($C$6:D14)+18,0) -> #VALUE! | E14: =VLOOKUP($B14,DADOS_ABBUD[],COLUMNS($C$6:D14)+10,FALSE) -> 300
B15: ='LEG ESTUDO DE MASSAS'!$B16 -> EUUN | C15: =VLOOKUP($B15,DADOS_ABBUD[],COLUMNS($C$5:C14)+2,0) -> Eugenia uniflora | D15: =VLOOKUP($B15,DADOS_ABBUD[],COLUMNS($C$6:D15)+18,0) -> #VALUE! | E15: =VLOOKUP($B15,DADOS_ABBUD[],COLUMNS($C$6:D15)+10,FALSE) -> 300
B16: ='LEG ESTUDO DE MASSAS'!$B17 -> GAJA | C16: =VLOOKUP($B16,DADOS_ABBUD[],COLUMNS($C$5:C15)+2,0) -> Gardenia jasminoides | D16: =VLOOKUP($B16,DADOS_ABBUD[],COLUMNS($C$6:D16)+18,0) -> #VALUE! | E16: =VLOOKUP($B16,DADOS_ABBUD[],COLUMNS($C$6:D16)+10,FALSE) -> 80
B17: ='LEG ESTUDO DE MASSAS'!$B18 -> HACH | C17: =VLOOKUP($B17,DADOS_ABBUD[],COLUMNS($C$5:C16)+2,0) -> Handroanthus chrysotrichus (Tabebuia chrysotricha) | D17: =VLOOKUP($B17,DADOS_ABBUD[],COLUMNS($C$6:D17)+18,0) -> #VALUE! | E17: =VLOOKUP($B17,DADOS_ABBUD[],COLUMNS($C$6:D17)+10,FALSE) -> 0
B18: ='LEG ESTUDO DE MASSAS'!$B19 -> HAIM | C18: =VLOOKUP($B18,DADOS_ABBUD[],COLUMNS($C$5:C17)+2,0) -> Handroanthus impetiginosus (Tabebuia impetiginosa ) | D18: =VLOOKUP($B18,DADOS_ABBUD[],COLUMNS($C$6:D18)+18,0) -> #VALUE! | E18: =VLOOKUP($B18,DADOS_ABBUD[],COLUMNS($C$6:D18)+10,FALSE) -> 0
B19: ='LEG ESTUDO DE MASSAS'!$B20 -> HEBI | C19: =VLOOKUP($B19,DADOS_ABBUD[],COLUMNS($C$5:C18)+2,0) -> Heliconia bihai | D19: =VLOOKUP($B19,DADOS_ABBUD[],COLUMNS($C$6:D19)+18,0) -> #VALUE! | E19: =VLOOKUP($B19,DADOS_ABBUD[],COLUMNS($C$6:D19)+10,FALSE) -> 200
B20: ='LEG ESTUDO DE MASSAS'!$B21 -> HEPS | C20: =VLOOKUP($B20,DADOS_ABBUD[],COLUMNS($C$5:C19)+2,0) -> Heliconia psittacorum | D20: =VLOOKUP($B20,DADOS_ABBUD[],COLUMNS($C$6:D20)+18,0) -> #VALUE! | E20: =VLOOKUP($B20,DADOS_ABBUD[],COLUMNS($C$6:D20)+10,FALSE) -> 100
B21: ='LEG ESTUDO DE MASSAS'!$B22 -> JACU | C21: =VLOOKUP($B21,DADOS_ABBUD[],COLUMNS($C$5:C20)+2,0) -> Jacaranda cuspidifolia | D21: =VLOOKUP($B21,DADOS_ABBUD[],COLUMNS($C$6:D21)+18,0) -> #VALUE! | E21: =VLOOKUP($B21,DADOS_ABBUD[],COLUMNS($C$6:D21)+10,FALSE) -> 300
B22: ='LEG ESTUDO DE MASSAS'!$B23 -> JAME | C22: =VLOOKUP($B22,DADOS_ABBUD[],COLUMNS($C$5:C21)+2,0) -> Jasminum mesnyi | D22: =VLOOKUP($B22,DADOS_ABBUD[],COLUMNS($C$6:D22)+18,0) -> #VALUE! | E22: =VLOOKUP($B22,DADOS_ABBUD[],COLUMNS($C$6:D22)+10,FALSE) -> 30
... B29: ='LEG ESTUDO DE MASSAS'!$B30 -> MEER | C29: =VLOOKUP($B29,DADOS_ABBUD[],COLUMNS($C$5:C28)+2,0) -> Megaskepasma erythrochlamys | D29: =VLOOKUP($B29,DADOS_ABBUD[],COLUMNS($C$6:D29)+18,0) -> #VALUE! | E29: =VLOOKUP($B29,DADOS_ABBUD[],COLUMNS($C$6:D29)+10,FALSE) -> 120
B30: ASGA | C30: =VLOOKUP($B30,DADOS_ABBUD[],COLUMNS($C$5:C29)+2,0) -> Asystasia gangetica | D30: =VLOOKUP($B30,DADOS_ABBUD[],COLUMNS($C$6:D30)+18,0) -> #VALUE! | E30: =VLOOKUP($B30,DADOS_ABBUD[],COLUMNS($C$6:D30)+10,FALSE) -> 20
B31: ='LEG ESTUDO DE MASSAS'!$B32 -> OPJB VA | C31: =VLOOKUP($B31,DADOS_ABBUD[],COLUMNS($C$5:C30)+2,0) -> Ophiopogon jaburan | D31: =VLOOKUP($B31,DADOS_ABBUD[],COLUMNS($C$6:D31)+18,0) -> #VALUE! | E31: =VLOOKUP($B31,DADOS_ABBUD[],COLUMNS($C$6:D31)+10,FALSE) -> 20
B32: ='LEG ESTUDO DE MASSAS'!$B33 -> OPJB VD | C32: =VLOOKUP($B32,DADOS_ABBUD[],COLUMNS($C$5:C31)+2,0) -> Ophiopogon jaburan | D32: =VLOOKUP($B32,DADOS_ABBUD[],COLUMNS($C$6:D32)+18,0) -> #VALUE! | E32: =VLOOKUP($B32,DADOS_ABBUD[],COLUMNS($C$6:D32)+10,FALSE) -> 20
B33: ='LEG ESTUDO DE MASSAS'!$B34 -> PAUT | C33: =VLOOKUP($B33,DADOS_ABBUD[],COLUMNS($C$5:C32)+2,0) -> Pandanus utilis | D33: =VLOOKUP($B33,DADOS_ABBUD[],COLUMNS($C$6:D33)+18,0) -> #VALUE! | E33: 200
B34: THBI | C34: =VLOOKUP($B34,DADOS_ABBUD[],COLUMNS($C$5:C33)+2,0) -> Thaumatophyllum bipinnatifidum (Philodendron bipinnatifidum) | D34: =VLOOKUP($B34,DADOS_ABBUD[],COLUMNS($C$6:D34)+18,0) -> #VALUE! | E34: =VLOOKUP($B34,DADOS_ABBUD[],COLUMNS($C$6:D34)+10,FALSE) -> 0
B35: ='LEG ESTUDO DE MASSAS'!$B36 -> PESE VD | C35: =VLOOKUP($B35,DADOS_ABBUD[],COLUMNS($C$5:C34)+2,0) -> Pennisetum setaceum | D35: =VLOOKUP($B35,DADOS_ABBUD[],COLUMNS($C$6:D35)+18,0) -> #VALUE! | E35: =VLOOKUP($B35,DADOS_ABBUD[],COLUMNS($C$6:D35)+10,FALSE) -> 40
B36: ='LEG ESTUDO DE MASSAS'!$B37 -> PHRN | C36: =VLOOKUP($B36,DADOS_ABBUD[],COLUMNS($C$5:C35)+2,0) -> Philodendron renauxii | D36: =VLOOKUP($B36,DADOS_ABBUD[],COLUMNS($C$6:D36)+18,0) -> #VALUE! | E36: =VLOOKUP($B36,DADOS_ABBUD[],COLUMNS($C$6:D36)+10,FALSE) -> 100
B37: ='LEG ESTUDO DE MASSAS'!$B38 -> PLRU | C37: =VLOOKUP($B37,DADOS_ABBUD[],COLUMNS($C$5:C36)+2,0) -> Plumeria rubra | D37: =VLOOKUP($B37,DADOS_ABBUD[],COLUMNS($C$6:D37)+18,0) -> #VALUE! | E37: =VLOOKUP($B37,DADOS_ABBUD[],COLUMNS($C$6:D37)+10,FALSE) -> 300
B38: ='LEG ESTUDO DE MASSAS'!$B39 -> PLSP | C38: =VLOOKUP($B38,DADOS_ABBUD[],COLUMNS($C$5:C37)+2,0) -> Plumeria speciosa | D38: =VLOOKUP($B38,DADOS_ABBUD[],COLUMNS($C$6:D38)+18,0) -> #VALUE! | E38: =VLOOKUP($B38,DADOS_ABBUD[],COLUMNS($C$6:D38)+10,FALSE) -> 300
B39: ='LEG ESTUDO DE MASSAS'!$B40 -> PTSC | C39: =VLOOKUP($B39,DADOS_ABBUD[],COLUMNS($C$5:C38)+2,0) -> Ptychosperma schefferi | D39: =VLOOKUP($B39,DADOS_ABBUD[],COLUMNS($C$6:D39)+18,0) -> #VALUE! | E39: =VLOOKUP($B39,DADOS_ABBUD[],COLUMNS($C$6:D39)+10,FALSE) -> 0
B40: ='LEG ESTUDO DE MASSAS'!$B41 -> SPTR | C40: =VLOOKUP($B40,DADOS_ABBUD[],COLUMNS($C$5:C39)+2,0) -> Sphagneticola trilobata(Wedelia paludaris) | D40: =VLOOKUP($B40,DADOS_ABBUD[],COLUMNS($C$6:D40)+18,0) -> #VALUE! | E40: =VLOOKUP($B40,DADOS_ABBUD[],COLUMNS($C$6:D40)+10,FALSE) -> 0
B41: ='LEG ESTUDO DE MASSAS'!$B42 -> STRE | C41: =VLOOKUP($B41,DADOS_ABBUD[],COLUMNS($C$5:C40)+2,0) -> Strelitzia reginae | D41: =VLOOKUP($B41,DADOS_ABBUD[],COLUMNS($C$6:D41)+18,0) -> #VALUE! | E41: =VLOOKUP($B41,DADOS_ABBUD[],COLUMNS($C$6:D41)+10,FALSE) -> 80
B42: ='LEG ESTUDO DE MASSAS'!$B43 -> THBI | C42: =VLOOKUP($B42,DADOS_ABBUD[],COLUMNS($C$5:C41)+2,0) -> Thaumatophyllum bipinnatifidum (Philodendron bipinnatifidum) | D42: =VLOOKUP($B42,DADOS_ABBUD[],COLUMNS($C$6:D42)+18,0) -> #VALUE! | E42: =VLOOKUP($B42,DADOS_ABBUD[],COLUMNS($C$6:D42)+10,FALSE) -> 0
B43: PHRN | C43: =VLOOKUP($B43,DADOS_ABBUD[],COLUMNS($C$5:C42)+2,0) -> Philodendron renauxii | D43: =VLOOKUP($B43,DADOS_ABBUD[],COLUMNS($C$6:D43)+18,0) -> #VALUE! | E43: =VLOOKUP($B43,DADOS_ABBUD[],COLUMNS($C$6:D43)+10,FALSE) -> 100
B44: MEER | C44: =VLOOKUP($B44,DADOS_ABBUD[],COLUMNS($C$5:C43)+2,0) -> Megaskepasma erythrochlamys | D44: =VLOOKUP($B44,DADOS_ABBUD[],COLUMNS($C$6:D44)+18,0) -> #VALUE! | E44: =VLOOKUP($B44,DADOS_ABBUD[],COLUMNS($C$6:D44)+10,FALSE) -> 120

Sheet uso interno PLANILHA
A1: LEGENDA DE ESPÉCIES 03/2026 | E1: 46098 | W1: SENHA DESBLOQUEIO
A2: ÁRVORES/ 1. PALMEIRAS/ 5. ARBUSTOS/ FORRAÇÕES | W2: em verde novas
A3: COD | B3: TIPO | C3: NOME CIENTIFICO | D3: NOME POPULAR | E3: COR | F3: Coluna1 | G3: ORIGEM | H3: INSOLAÇÃO | I3: COMPORTAMENTO | J3: TOXIDADE | K3: FLORESCE | L3: PORTE cm | M3: copa(m) | N3: Perfume | O3: SOLO | P3: TOLERÂNCIA | Q3: OCORRÊNCIA | R3: COD ANTIGO | S3: CARACTERÍSTICAS | T3: FOTO | U3: BABBUD UTILIZA | V3: PORTE ADULTO
A4: ACWR | B4: 1. PALMEIRA | C4: Acoelorraphe wrightii | D4: Palmeira paorotis | G4: nativa | L4: 300 | R4: =DADOS_ABBUD[[#This Row],[COD]] -> ACWR | T4: =_xlfn.XLOOKUP(DADOS_ABBUD[[#This Row],[COD]],'uso interno FOTOS'!A:A,'uso interno FOTOS'!B:B) -> #N/A | U4: 3 | V4: 0,2-0,4
A5: ACAC | B5: 1. PALMEIRA | C5: Acrocomia aculeata | D5: Macaúba | G5: nativa | L5: 300 | R5: =DADOS_ABBUD[[#This Row],[COD]] -> ACAC | T5: =_xlfn.XLOOKUP(DADOS_ABBUD[[#This Row],[COD]],'uso interno FOTOS'!A:A,'uso interno FOTOS'!B:B) -> #VALUE! | U5: 1
A6: AIHO | B6: 1. PALMEIRA | C6: Aiphanes horrida (Aiphanes aculeata) | D6: Caryota de espinho | G6: nativa | R6: AIAC | T6: =_xlfn.XLOOKUP(DADOS_ABBUD[[#This Row],[COD]],'uso interno FOTOS'!A:A,'uso interno FOTOS'!B:B) -> #N/A | U6: 2
A7: ALAR | B7: 1. PALMEIRA | C7: Allagoptera arenaria | D7: Caxandó | G7: nativa | L7: 200 | R7: =DADOS_ABBUD[[#This Row],[COD]] -> ALAR | T7: =_xlfn.XLOOKUP(DADOS_ABBUD[[#This Row],[COD]],'uso interno FOTOS'!A:A,'uso interno FOTOS'!B:B) -> #N/A | U7: 3 | V7: 3-4
A8: ALBR | B8: 1. PALMEIRA | C8: Allagoptera brevicalyx | D8: Pissandó | G8: nativa | L8: 200 | R8: =DADOS_ABBUD[[#This Row],[COD]] -> ALBR | T8: =_xlfn.XLOOKUP(DADOS_ABBUD[[#This Row],[COD]],'uso interno FOTOS'!A:A,'uso interno FOTOS'!B:B) -> #N/A | U8: 3 | V8: 3-6
A9: ALCD | B9: 1. PALMEIRA | C9: Allagoptera caudescens (Polyandrococos caudescens) | D9: Buri | G9: nativa | R9: POCC | T9: =_xlfn.XLOOKUP(DADOS_ABBUD[[#This Row],[COD]],'uso interno FOTOS'!A:A,'uso interno FOTOS'!B:B) -> #N/A | U9: 3 | V9: 3-6
A10: ARCA | B10: 1. PALMEIRA | C10: Areca cathechu | D10: Areca-betel | G10: exótica adaptada | L10: 300 | R10: =DADOS_ABBUD[[#This Row],[COD]] -> ARCA | T10: =_xlfn.XLOOKUP(DADOS_ABBUD[[#This Row],[COD]],'uso interno FOTOS'!A:A,'uso interno FOTOS'!B:B) -> #N/A | U10: 3
A11: ARTR | B11: 1. PALMEIRA | C11: Areca triandra | D11: Areca triandra | G11: exótica adaptada | H11: sombra | L11: 200 | R11: =DADOS_ABBUD[[#This Row],[COD]] -> ARTR | T11: =_xlfn.XLOOKUP(DADOS_ABBUD[[#This Row],[COD]],'uso interno FOTOS'!A:A,'uso interno FOTOS'!B:B) -> #VALUE! | U11: 1
A12: ARVE | B12: 1. PALMEIRA | C12: Areca vestiaria | D12: Areca dourada | G12: exótica adaptada | H12: sol | L12: 350 | R12: =DADOS_ABBUD[[#This Row],[COD]] -> ARVE | T12: =_xlfn.XLOOKUP(DADOS_ABBUD[[#This Row],[COD]],'uso interno FOTOS'!A:A,'uso interno FOTOS'!B:B) -> #VALUE! | U12: 1
A13: ASAC | B13: 1. PALMEIRA | C13: Astrocaryum aculeatum | D13: Tucumã | G13: nativa | L13: 100 | R13: =DADOS_ABBUD[[#This Row],[COD]] -> ASAC | T13: =_xlfn.XLOOKUP(DADOS_ABBUD[[#This Row],[COD]],'uso interno FOTOS'!A:A,'uso interno FOTOS'!B:B) -> #N/A | U13: 2
A14: ATDU | B14: 1. PALMEIRA | C14: Attalea dubia | D14: Coqueiro idaiá | G14: nativa | L14: 300 | R14: =DADOS_ABBUD[[#This Row],[COD]] -> ATDU | T14: =_xlfn.XLOOKUP(DADOS_ABBUD[[#This Row],[COD]],'uso interno FOTOS'!A:A,'uso interno FOTOS'!B:B) -> #N/A | U14: 3
A15: ATEX | B15: 1. PALMEIRA | C15: Attalea exigua | D15: Coco-catolé | E15: VERMELHO | G15: nativa | L15: 150 | R15: =DADOS_ABBUD[[#This Row],[COD]] -> ATEX | T15: =_xlfn.XLOOKUP(DADOS_ABBUD[[#This Row],[COD]],'uso interno FOTOS'!A:A,'uso interno FOTOS'!B:B) -> #N/A | U15: 3
A16: ATSP | B16: 1. PALMEIRA | C16: Attalea speciosa | D16: Babaçu | G16: nativa | L16: 300 | R16: =DADOS_ABBUD[[#This Row],[COD]] -> ATSP | T16: =_xlfn.XLOOKUP(DADOS_ABBUD[[#This Row],[COD]],'uso interno FOTOS'!A:A,'uso interno FOTOS'!B:B) -> #N/A | U16: 3
A17: BAGA | B17: 1. PALMEIRA | C17: Bactris gasipaes | D17: Pupunha | G17: nativa | H17: sol | L17: 300 | R17: =DADOS_ABBUD[[#This Row],[COD]] -> BAGA | T17: =_xlfn.XLOOKUP(DADOS_ABBUD[[#This Row],[COD]],'uso interno FOTOS'!A:A,'uso interno FOTOS'!B:B) -> #N/A | U17: 1
A18: BINO | B18: 1. PALMEIRA | C18: Bismarckia nobilis | D18: palmeira azul | G18: exótica adaptada | H18: sol | R18: =DADOS_ABBUD[[#This Row],[COD]] -> BINO | T18: =_xlfn.XLOOKUP(DADOS_ABBUD[[#This Row],[COD]],'uso interno FOTOS'!A:A,'uso interno FOTOS'!B:B) -> #VALUE! | U18: 1
A19: BUCA | B19: 1. PALMEIRA | C19: Butia capitata | D19: Butia | G19: nativa | H19: sol | L19: 300 | R19: =DADOS_ABBUD[[#This Row],[COD]] -> BUCA | T19: =_xlfn.XLOOKUP(DADOS_ABBUD[[#This Row],[COD]],'uso interno FOTOS'!A:A,'uso interno FOTOS'!B:B) -> #VALUE! | U19: 1
A20: CAAC | B20: 1. PALMEIRA | C20: Carpentaria acuminata | D20: Carpentaria | G20: exótica adaptada | H20: sol | R20: =DADOS_ABBUD[[#This Row],[COD]] -> CAAC | T20: =_xlfn.XLOOKUP(DADOS_ABBUD[[#This Row],[COD]],'uso interno FOTOS'!A:A,'uso interno FOTOS'!B:B) -> #VALUE! | U20: 1
A21: CAMI | B21: 1. PALMEIRA | C21: Caryota mitis | D21: palmeira rabo de peixe | G21: exótica adaptada | H21: sol/ meia sombra | L21: 300 | R21: =DADOS_ABBUD[[#This Row],[COD]] -> CAMI | T21: =_xlfn.XLOOKUP(DADOS_ABBUD[[#This Row],[COD]],'uso interno FOTOS'!A:A,'uso interno FOTOS'!B:B) -> #N/A | U21: 2
A22: CAUR | B22: 1. PALMEIRA | C22: Caryota urens | D22: Cariota | G22: exótica adaptada | L22: 300 | R22: =DADOS_ABBUD[[#This Row],[COD]] -> CAUR | T22: =_xlfn.XLOOKUP(DADOS_ABBUD[[#This Row],[COD]],'uso interno FOTOS'!A:A,'uso interno FOTOS'!B:B) -> #N/A | U22: 3
A23: CHEL | B23: 1. PALMEIRA | C23: Chamaedorea elegans | D23: Chamaedorea elegante | G23: exótica adaptada | H23: sombra | L23: 180 | R23: =DADOS_ABBUD[[#This Row],[COD]] -> CHEL | T23: =_xlfn.XLOOKUP(DADOS_ABBUD[[#This Row],[COD]],'uso interno FOTOS'!A:A,'uso interno FOTOS'!B:B) -> #VALUE! | U23: 1
A24: CHMI | B24: 1. PALMEIRA | C24: Chamaedorea microspadix | D24: Palmeirinha bambu | G24: exótica adaptada | L24: 150 | R24: =DADOS_ABBUD[[#This Row],[COD]] -> CHMI | T24: =_xlfn.XLOOKUP(DADOS_ABBUD[[#This Row],[COD]],'uso interno FOTOS'!A:A,'uso interno FOTOS'!B:B) -> #VALUE! | U24: 3
A25: CHST | B25: 1. PALMEIRA | C25: Chamaedorea stolonifera | D25: Chamaedorea stolonifera | G25: exótica adaptada | L25: 100 | R25: =DADOS_ABBUD[[#This Row],[COD]] -> CHST | T25: =_xlfn.XLOOKUP(DADOS_ABBUD[[#This Row],[COD]],'uso interno FOTOS'!A:A,'uso interno FOTOS'!B:B) -> #VALUE! | U25: 3
A26: CHTE | B26: 1. PALMEIRA | C26: Chamaedorea tepejilote | D26: Camaedorea pacaia | G26: exótica adaptada | L26: 200 | R26: =DADOS_ABBUD[[#This Row],[COD]] -> CHTE | T26: =_xlfn.XLOOKUP(DADOS_ABBUD[[#This Row],[COD]],'uso interno FOTOS'!A:A,'uso interno FOTOS'!B:B) -> #VALUE! | U26: 3
A27: CHHU | B27: 1. PALMEIRA | C27: Chamaerops humilis | D27: palmeira do mediterrâneo | G27: exótica adaptada | L27: 180 | R27: =DADOS_ABBUD[[#This Row],[COD]] -> CHHU | T27: =_xlfn.XLOOKUP(DADOS_ABBUD[[#This Row],[COD]],'uso interno FOTOS'!A:A,'uso interno FOTOS'!B:B) -> #N/A | U27: 2
A28: CONU | B28: 1. PALMEIRA | C28: Cocus nucifera | D28: Coco da Bahia | G28: exótica adaptada | H28: sol | L28: 300 | R28: =DADOS_ABBUD[[#This Row],[COD]] -> CONU | T28: =_xlfn.XLOOKUP(DADOS_ABBUD[[#This Row],[COD]],'uso interno FOTOS'!A:A,'uso interno FOTOS'!B:B) -> #VALUE! | U28: 1
A29: CONN | B29: 1. PALMEIRA | C29: Cocus nucifera nana | D29: Coco anao | G29: exótica adaptada | H29: sol | L29: 300 | R29: =DADOS_ABBUD[[#This Row],[COD]] -> CONN | T29: =_xlfn.XLOOKUP(DADOS_ABBUD[[#This Row],[COD]],'uso interno FOTOS'!A:A,'uso interno FOTOS'!B:B) -> #VALUE! | U29: 1
A30: COAL | B30: 1. PALMEIRA | C30: Copernicia alba | D30: Carandá | G30: nativa | H30: sol | R30: =DADOS_ABBUD[[#This Row],[COD]] -> COAL | T30: =_xlfn.XLOOKUP(DADOS_ABBUD[[#This Row],[COD]],'uso interno FOTOS'!A:A,'uso interno FOTOS'!B:B) -> #VALUE! | U30: 2
A31: COPR | B31: 1. PALMEIRA | C31: Copernicia prunifera | D31: Carnauba | G31: nativa | H31: sol | R31: =DADOS_ABBUD[[#This Row],[COD]] -> COPR | T31: =_xlfn.XLOOKUP(DADOS_ABBUD[[#This Row],[COD]],'uso interno FOTOS'!A:A,'uso interno FOTOS'!B:B) -> #VALUE! | U31: 1
A32: CYTA | B32: 1. PALMEIRA | C32: Cycas taitungensis | D32: Sagu do imperador | G32: exótica adaptada | R32: =DADOS_ABBUD[[#This Row],[COD]] -> CYTA | T32: =_xlfn.XLOOKUP(DADOS_ABBUD[[#This Row],[COD]],'uso interno FOTOS'!A:A,'uso interno FOTOS'!B:B) -> #N/A | U32: 3
A33: CYRB | B33: 1. PALMEIRA | C33: Cyrtostachys renda Blume( Cyrtostachys lakka) | D33: palmeira laka | G33: exótica adaptada | H33: sol/ meia sombra | R33: CYLA | T33: =_xlfn.XLOOKUP(DADOS_ABBUD[[#This Row],[COD]],'uso interno FOTOS'!A:A,'uso interno FOTOS'!B:B) -> #VALUE! | U33: 2
A34: DIAL | B34: 1. PALMEIRA | C34: Dictyosperma album | D34: palmeira princesa | G34: exótica adaptada | H34: sol | L34: 300 | R34: =DADOS_ABBUD[[#This Row],[COD]] -> DIAL | T34: =_xlfn.XLOOKUP(DADOS_ABBUD[[#This Row],[COD]],'uso interno FOTOS'!A:A,'uso interno FOTOS'!B:B) -> #VALUE! | U34: 2
A35: DYDE | B35: 1. PALMEIRA | C35: Dypsis decaryi (Neodypsis decaryi) | D35: Neodypsis | G35: exótica adaptada | H35: sol | M35: 3-6 | O35: arenoso, salinos | P35: maresias, não tolera frio | Q35: Madagascar, savanas, altitudes 80-600m | R35: NEDE | S35: difundida em SP e RJ, frutos comestiveis | T35: =_xlfn.XLOOKUP(DADOS_ABBUD[[#This Row],[COD]],'uso interno FOTOS'!A:A,'uso interno FOTOS'!B:B) -> #VALUE! | U35: 1 | V35: 5-8
A36: DYLE | B36: 1. PALMEIRA | C36: Dypsis leptocheilos | D36: Palmeira do pescoço marrom | G36: exótica adaptada | L36: 300 | R36: =DADOS_ABBUD[[#This Row],[COD]] -> DYLE | T36: =_xlfn.XLOOKUP(DADOS_ABBUD[[#This Row],[COD]],'uso interno FOTOS'!A:A,'uso interno FOTOS'!B:B) -> #VALUE! | U36: 3
A37: DYLU | B37: 1. PALMEIRA | C37: Dypsis lutescens (Chrysalidocarpus lutescens LU) | D37: Areca c/ folhas embaixo | G37: exótica adaptada | H37: sol | L37: 150 | R37: CHLU | T37: =_xlfn.XLOOKUP(DADOS_ABBUD[[#This Row],[COD]],'uso interno FOTOS'!A:A,'uso interno FOTOS'!B:B) -> #VALUE! | U37: 1
A38: DYLL | B38: 1. PALMEIRA | C38: Dypsis lutescens (Chrysalidocarpus lutescens LL) | D38: Areca s/ folhas embaixo | G38: exótica adaptada | H38: sol | L38: 150 | R38: CHLL | T38: =_xlfn.XLOOKUP(DADOS_ABBUD[[#This Row],[COD]],'uso interno FOTOS'!A:A,'uso interno FOTOS'!B:B) -> #VALUE! | U38: 1
A39: DYMA | B39: 1. PALMEIRA | C39: Dypsis madagascariensis | D39: Areca de locuba | G39: exótica adaptada | H39: sol | L39: 300 | R39: =DADOS_ABBUD[[#This Row],[COD]] -> DYMA | T39: =_xlfn.XLOOKUP(DADOS_ABBUD[[#This Row],[COD]],'uso interno FOTOS'!A:A,'uso interno FOTOS'!B:B) -> #VALUE! | U39: 1
A40: ELOL | B40: 1. PALMEIRA | C40: Elaeis oleifera | D40: Dendê do pará | G40: nativa | L40: 300 | R40: =DADOS_ABBUD[[#This Row],[COD]] -> ELOL | T40: =_xlfn.XLOOKUP(DADOS_ABBUD[[#This Row],[COD]],'uso interno FOTOS'!A:A,'uso interno FOTOS'!B:B) -> #N/A | U40: 3
...

Sheet uso interno FOTOS
D1: COD. ANTIGO | E1: COD. NOVO | F1: NOME | G1: NOME
A2: CÓDIGO | B2: FOTO | D2: wepa | E2: =_xlfn.XLOOKUP(D$2,'uso interno PLANILHA'!R:R,'uso interno PLANILHA'!A:A,0) -> SPTR | F2: =_xlfn.XLOOKUP(E$2,'uso interno PLANILHA'!A:A,'uso interno PLANILHA'!C:C,0) -> Sphagneticola trilobata(Wedelia paludaris) | G2: =_xlfn.XLOOKUP(E$2,'uso interno PLANILHA'!A:A,'uso interno PLANILHA'!D:D,0) -> Dorinha
A3: ABGR | B3: #VALUE! | D3: ]
A4: ABHY | B4: #VALUE!
A5: ABPI | B5: #VALUE!
A6: ACAC | B6: #VALUE!
A7: ACAU | B7: #VALUE!
A8: ACPA | B8: #VALUE!
A9: ACPD | B9: #VALUE!
A10: ACSE | B10: #VALUE!
A11: AGAF | B11: #VALUE!
A12: AGAM | B12: #VALUE!
A13: AGAN | B13: #VALUE!
A14: AGAT | B14: #VALUE!
A15: AGCO | B15: #VALUE!
... A43: ANLE | B43: #VALUE!
A44: ANMA
A45: ANMU | B45: #VALUE!
A46: ANOC | B46: #VALUE!
A47: ANPL | B47: #VALUE!
A48: ANSC | B48: #VALUE!
A49: ANSQ | B49: #VALUE!
A50: APCO | B50: #VALUE!
A51: APSQ | B51: #VALUE!
A52: ARAL | B52: #VALUE!
A53: ARAN | B53: #VALUE!
A54: ARBA | B54: #VALUE!
A55: AREI | B55: #VALUE!
A56: ARIN | B56: #VALUE!
... A153: CONN | B153: #VALUE!
A154: CONU | B154: #VALUE! | J154: S
A155: COPR | B155: #VALUE!
A156: COSE | B156: #VALUE!
A157: COSL | B157: #VALUE!
A158: COTB | B158: #VALUE!
A159: COTE | B159: #VALUE!
A160: COTO | B160: #VALUE!
A161: COTR | B161: #VALUE!
A162: COUV | B162: #VALUE!
A163: COVA | B163: #VALUE!
...

Sheet BASE
I2: PARA QUEM ESTIVER AJUSTANDO | L2: CONTROLE DE REVISÕES
B3: ORIGEM | D3: INSOLAÇÃO | F3: COMPORTAMENTO | I3: em azul nova nomenclatura, (nomes incorretos) | L3: DATA | M3: REVISÃO | N3: DESCRIÇÃO | O3: RESPONSÁVEL
B4: nativa | D4: sol | F4: ereta | I4: precisa eliminar duplicados forração, arbusto | L4: 45553 | M4: R0D | N4: emissão inical | O4: CHRISTINA | Q4: ERRO
B5: exótica adaptada | D5: meia sombra | F5: pendente | I5: roxo atualizado mtz | L5: 45579 | M5: R0E | N5: inserção de fotos e ajustes dados | O5: CHRISTINA | Q5: quando não aparece a foto é porque existe código duplicado
D6: sol/ meia sombra | F6: reptante | I6: VERMELHO - DÚVIDAS | L6: 45866 | M6: R0F | N6: inclusão de novas espécies e fotos | O6: CHRISTINA
D7: sombra | I7: novas espécies
D8: meia sombra/sombra
B11: BABBUD UTILIZA
A12: 1 | B12: 1 FREQUENTE
A13: 2 | B13: 2 ESPORÁDICO | I13: 1. PALMEIRA
A14: 3 | B14: 3 RARAMENTE | I14: 2. ARV NATIVA
I15: 3. ARV EXOT
I16: 4. ARV FRUT
I17: 5. ARBUSTO
I18: 6. FORRAÇÃO
I19: 7. AQUÁTICA
I20: 7. BROMÉLIA
I21: 7. CACTO
I22: 8. ACABAMEN

Sheet MTZ
A1: _NOME CIENTÍFICO | B1: _NOME POPULAR | C1: ORIGEM | D1: _SL | E1: _MS | F1: _SO | G1: _BR | H1: _PA | I1: _CO | J1: _ARB | K1: _FOR | L1: _TREP | M1: _EPF | N1: _PERF | O1: _ERET | P1: _PEND | Q1: _REPT | R1: _CLAR | S1: _MÉD | T1: _ESCU | U1: _COR | V1: _PRAT | W1: _VAR | X1: _IT | Y1: _SO | Z1: _MA | AA1: _DISP | AB1: _FORN | AC1: ALT(cm) | AD1: DIÂM(cm) | AE1: CARACTERÍSTICAS | AF1: IMPORT | AG1: SUBST
A2: Abelia grandiflora | B2: Abélia | C2: exótica | D2: x | G2: x | J2: x | O2: x | S2: x | X2: x | AA2: 2 | AC2: 100 | AD2: 100 | AE2: arbusto cheio | AF2: ** | AG2: insubstituível
A3: Abutilon megapotamicum | B3: Lanterna-chinesa | C3: exótica | D3: x | E3: x | I3: x | J3: x | L3: x | P3: x | S3: x | Z3: x | AA3: 3 | AC3: 60 | AD3: 50 | AE3: arbusto cheio | AF3: ** | AG3: insubstituível
A4: Acca sellowiana | B4: Goiaba-da-serra | C4: nativa | D4: x | H4: x | J4: x | O4: x | R4: x | X4: x | Y4: x | Z4: x | AA4: 2 | AB4: Fábrica de Árvores | AC4: 100 | AD4: 100 | AE4: arbusto cheio | AF4: *** | AG4: insubstituível
A5: Acorus gramineus | B5: Acorus | C5: exótica | D5: x | E5: x | K5: x | N5: x | O5: x | R5: x | X5: x | Y5: x | Z5: x | AA5: 2 | AC5: 30 | AD5: 40 | AE5: planta adulta | AF5: **** | AG5: Ophiopogon variegata
A6: Adiantum macrophyllum | B6: Avencão | C6: nativa | E6: x | F6: x | K6: x | O6: x | P6: x | R6: x | S6: x | X6: x | Y6: x | Z6: x | AA6: 2 | AC6: 30 | AD6: 20 | AF6: **** | AG6: insubstituível
A7: Adiantum pedatum | B7: Avenca-americana | C7: exótica | E7: x | F7: x | K7: x | O7: x | R7: x | S7: x | X7: x | Y7: x | Z7: x | AA7: 3 | AC7: 30 | AD7: 30 | AE7: arbusto cheio | AF7: *** | AG7: insubstituível
A8: Adiantum peruvianum | B8: Avencão | C8: nativa | E8: x | K8: x | O8: x | R8: x | S8: x | X8: x | Y8: x | Z8: x | AA8: 3 | AC8: 30 | AD8: 30 | AE8: touceira cheia | AF8: *** | AG8: insubstituível
A9: Adiantum raddianum | B9: Avenca | C9: nativa | E9: x | F9: x | J9: x | K9: x | S9: x | X9: x | Y9: x | Z9: x | AA9: 3 | AD9: 40 | AE9: planta adulta | AF9: *** | AG9: outras avencas
A10: Aechmea blanchetiana | B10: Bromélia-porto-seguro | C10: nativa | D10: x | E10: x | J10: x | R10: x | U10: x | Z10: x | AA10: 3 | AC10: 60 | AD10: 50 | AE10: planta adulta | AF10: ** | AG10: insubstituível
A11: Aechmea chantinii | B11: Bromélia-zebra | C11: nativa | E11: x | J11: x | M11: x | R11: x | V11: x | Z11: x | AA11: 2 | AC11: 40 | AD11: 30 | AE11: planta adulta | AF11: *** | AG11: insubstituível
A12: Aechmea fasciata | B12: Vaso-prateado | C12: nativa | E12: x | H12: x | J12: x | M12: x | V12: x | Z12: x | AA12: 3 | AC12: 40 | AD12: 30 | AE12: planta adulta | AF12: ** | AG12: insubstituível
A13: Agapanthus africanus | B13: Agapanto | C13: exótica | D13: x | E13: x | G13: x | H13: x | J13: x | K13: x | S13: x | X13: x | AA13: 3 | AC13: 30 | AE13: planta adulta | AF13: *** | AG13: insubstituível
A14: Allamanda blanchetti | B14: Alamanda-roxa | C14: nativa | D14: x | H14: x | L14: x | P14: x | T14: x | X14: x | Y14: x | Z14: x | AA14: 2 | AC14: 200 | AD14: 100 | AE14: arbusto cheio | AF14: *** | AG14: insubstituível
A15: Alocasia cucullata | B15: Alocasia | C15: exótica | D15: x | E15: x | F15: x | J15: x | T15: x | Z15: x | AA15: 2 | AC15: 50 | AD15: 50 | AE15: planta adulta | AF15: * | AG15: insubstituível
A16: Alocasia cuprea | B16: Pulmão-de-aço | C16: exótica | E16: x | J16: x | T16: x | Z16: x | AA16: 2 | AC16: 30 | AD16: 30 | AE16: planta adulta | AF16: *** | AG16: insubstituível
A17: Alocasia macrorrhiza | B17: Orelha-de-elefante | C17: exótica | D17: x | E17: x | J17: x | O17: x | R17: x | S17: x | Z17: x | AA17: 2 | AC17: 150 | AE17: mín. 6 folhas | AF17: ** | AG17: insubstituível
A18: Alocasia regal shield | B18: Alocasia-regal | C18: cultivada | E18: x | F18: x | J18: x | O18: x | U18: x | Y18: x | Z18: x | AA18: 1 | AB18: Campineira / Spagnol | AC18: 60 | AD18: 60 | AE18: mín. 6 folhas | AF18: *** | AG18: outras alocasias
A19: Alocasia wentii | C19: exótica | D19: x | E19: x | J19: x | S19: x | T19: x | Z19: x | AA19: 1 | AB19: J. Pompeo | AC19: 60 | AD19: 50 | AE19: arbusto cheio | AF19: ** | AG19: outras alocasias
A20: Alocasia x amazonica | B20: Punhal-malaio | C20: cultivada | E20: x | F20: x | J20: x | T20: x | Z20: x | AA20: 2 | AC20: 70 | AE20: mín. 6 folhas | AF20: * | AG20: insubstituível
A21: Aloysia virgata | B21: Folha-de-lixa | C21: nativa | D21: x | G21: x | J21: x | N21: x | O21: x | S21: x | X21: x | Y21: x | Z21: x | AA21: 1 | AB21: Fábrica de Árvores | AC21: 200 | AD21: 100 | AF21: *** | AG21: insubstituível
A22: Alpinia purpurata | B22: Alpínia | C22: exótica | D22: x | E22: x | I22: x | J22: x | O22: x | S22: x | Z22: x | AA22: 2 | AC22: 150 | AE22: mín. 6 hastes | AF22: * | AG22: tropicais de folha grande
A23: Alpinia sanderae | B23: Alpínia-variegada | C23: exótica | E23: x | J23: x | O23: x | W23: x | Z23: x | AA23: 1 | AB23: Floricultura Campineira | AC23: 120 | AD23: 70 | AE23: arbusto cheio | AF23: ** | AG23: Alpinia zerumbet
A24: Alpinia zerumbet | B24: Gengibre-concha | C24: exótica | D24: x | G24: x | J24: x | O24: x | W24: x | Z24: x | AA24: 2 | AC24: 150 | AE24: mín. 6 hastes | AF24: * | AG24: insubstituível
A25: Amphilophium paniculatum | B25: Cipó-de-água | C25: nativa | D25: x | H25: x | L25: x | S25: x | X25: x | Y25: x | AA25: 1 | AC25: 100 | AE25: trepadeira tutorada | AF25: **
A26: Anemone japonica | B26: Anêmona-do-japão | C26: exótica | D26: x | G26: x | H26: x | K26: x | S26: x | X26: x | AA26: 2 | AF26: ** | AG26: insubstituível
A27: Angelonia angustifolia | B27: Angelônia | C27: exótica | D27: x | G27: x | H27: x | K27: x | N27: x | O27: x | S27: x | X27: x | AA27: 2 | AC27: 30 | AD27: 25 | AE27: planta adulta | AF27: ** | AG27: insubstituível
A28: Anthurium amnicola | C28: exótica | E28: x | F28: x | H28: x | K28: x | S28: x | Y28: x | Z28: x | AA28: 1 | AB28: J. Pompeo | AC28: 30 | AD28: 20 | AE28: arbusto cheio | AF28: **** | AG28: insubstituível
A29: Anthurium andreanum | B29: Antúrio | C29: exótica | E29: x | F29: x | G29: x | I29: x | J29: x | K29: x | T29: x | Z29: x | AA29: 3 | AC29: 60 | AE29: planta adulta | AF29: * | AG29: insubstituível
A30: Anthurium brownii | B30: Antúrio-marrom | C30: nativa | E30: x | J30: x | K30: x | T30: x | Z30: x | AA30: 1 | AB30: J. Pompeo | AC30: 40 | AD30: 30 | AE30: arbusto cheio | AF30: *** | AG30: insubstituível
A31: Anthurium clavigerum | C31: nativa | E31: x | J31: x | L31: x | S31: x | Z31: x | AA31: 1 | AB31: J. Pompeo | AC31: 60 | AD31: 60 | AE31: arbusto cheio | AF31: *** | AG31: insubstituível
A32: Anthurium coriaceum | C32: nativa | E32: x | F32: x | J32: x | T32: x | Z32: x | AA32: 1 | AB32: J. Pompeo | AC32: 80 | AD32: 40 | AE32: arbusto cheio | AF32: **** | AG32: insubstituível
A33: Anthurium hookeri | C33: nativa | D33: x | E33: x | J33: x | M33: x | T33: x | Z33: x | AA33: 1 | AB33: J. Pompeo | AC33: 60 | AD33: 50 | AE33: arbusto cheio | AF33: ** | AG33: insubstituível
A34: Anthurium plowmanii | C34: nativa | E34: x | J34: x | S34: x | Z34: x | AA34: 1 | AB34: J. Pompeo | AC34: 60 | AD34: 40 | AE34: planta adulta | AF34: **** | AG34: insubstituível
A35: Antigonon leptopus | B35: Amor-agarradinho | C35: exótica | D35: x | I35: x | L35: x | P35: x | R35: x | X35: x | Y35: x | AA35: 3 | AC35: 300 | AE35: trepadeira tutorada | AF35: * | AG35: trepadeiras floridas
A36: Arachis repens | B36: Grama-amendoim | C36: nativa | D36: x | E36: x | K36: x | Q36: x | T36: x | X36: x | Y36: x | Z36: x | AA36: 3 | AC36: 10 | AF36: * | AG36: forrações nativas
A37: Aristea ecklonii | B37: Moréia-azul | C37: exótica | D37: x | E37: x | H37: x | K37: x | O37: x | S37: x | X37: x | Y37: x | AA37: 1 | AC37: 30 | AD37: 20 | AE37: touceira cheia | AF37: ** | AG37: outras flores azuis
A38: Aristolochia gigantea | B38: Papo-de-peru | C38: nativa | D38: x | H38: x | L38: x | P38: x | T38: x | Z38: x | AA38: 2 | AC38: 300 | AE38: trepadeira tutorada | AF38: * | AG38: trepadeiras incomuns
A39: Arundina bambusifolia | B39: Orquídea-bambu | C39: exótica | D39: x | E39: x | H39: x | J39: x | O39: x | R39: x | X39: x | AA39: 3 | AC39: 150 | AE39: mín. 4 hastes | AF39: **** | AG39: insubstituível
A40: Arundinaria japonica | B40: Bambu-metake | C40: exótica | D40: x | E40: x | J40: x | O40: x | S40: x | X40: x | Y40: x | Z40: x | AA40: 3 | AC40: 250 | AD40: 40 | AE40: touceira | AF40: *** | AG40: outros bambus
...
